<?xml version="1.0"?>
<robot name="kmr" xmlns:xacro="http://ros.org/wiki/xacro">

<link name="robot_odom"/>  
<link name="base_link_yaw"/>
<link name="x_link"/>

<joint name="X" type="prismatic">
            <parent link="robot_odom"/>
            <child link="x_link"/>
            <limit effort="1000.0" lower="-40.0" upper="40.0" velocity="10"/>
            <origin rpy="0 0 0" xyz="0 0 0"/>
            <axis xyz="1 0 0"/>
</joint>

<joint name="Y" type="prismatic">
            <parent link="x_link"/>
            <child link="base_link_yaw"/>
            <limit effort="1000.0" lower="-40.0" upper="40.0" velocity="10"/>
            <origin rpy="0 0 0" xyz="0 0 0"/>
            <axis xyz="0 1 0"/>
</joint>

<joint name="Yaw" type="revolute">
            <parent link="base_link_yaw"/>
            <child link="base_footprint"/>
            <origin rpy="0 0 0" xyz="0 0 0"/>
            <axis xyz="0 0 1"/>
            <limit effort="10.0" lower="-1000.0" upper="1000" velocity="5"/>
</joint>

  <link name="base_footprint"/>

  <joint name="bf" type="fixed">
      <parent link="base_footprint"/>
      <child link="base_link"/>
      <origin rpy="0 0 0.0" xyz="0 0 0.0775"/>
  </joint>

  <material name="Orange">
    <color rgba="1.0 0.4 0.0 1.0"/>
  </material>
  <material name="Grey">
    <color rgba="0.7 0.7 0.7 1.0"/>
  </material>
  <material name="DarkGrey">
    <color rgba="0.3 0.3 0.3 1.0"/>
  </material>
  <material name="White">
    <color rgba="1.0 1.0 1.0 1.0"/>
  </material>
  <material name="Black">
    <color rgba="0.0 0.0 0.0 1.0"/>
  </material>
  <material name="Red">
    <color rgba="1.0 0.0 0.0 1.0"/>
  </material>
  <material name="Green">
    <color rgba="0.0 1.0 0.0 1.0"/>
  </material>
  <material name="aluminum">
    <color rgba="0.5 0.5 0.5 1"/>
  </material>

  <link name="base_link">
      <visual>
        <geometry>
          <box size="1.08 0.63 0.085"/>
        </geometry>
        <origin rpy="0 0 0" xyz="0 0 0"/>
        <material name="Orange"/>
      </visual>
      <collision>
        <geometry>
          <box size="1.08 0.63 0.085"/>
        </geometry>
      </collision>
  </link>

  <joint name="base_bottom_to_middle_joint" type="fixed">
          <parent link="base_link" />
          <child link="base_link_middle" />
          <origin xyz="0 0 0.0665" rpy="0 0 0"/>
  </joint>

  <link name="base_link_middle">
      <visual>
        <geometry>
          <box size="0.84 0.48 0.048"/>
        </geometry>
        <origin rpy="0 0 0" xyz="0 0 0.0"/>
        <material name="Orange"/>
      </visual>
      <collision>
        <geometry>
          <box size="0.920 0.51 0.055"/>
        </geometry>
      </collision>
    </link>

  <joint name="base_middle_to_top_joint" type="fixed">
          <parent link="base_link_middle" />
          <child link="base_link_top" />
          <origin xyz="0 0 0.2865" rpy="0 0 0"/>
  </joint>

  <link name="base_link_top">
      <visual>
        <geometry>
          <box size="1.08 0.63 0.525"/>
        </geometry>
        <origin rpy="0 0 0" xyz="0 0 0.0"/>
        <material name="Grey"/>
      </visual>
      <collision>
        <geometry>
          <box size="1.08 0.63 0.5335"/>
        </geometry>
      </collision>
  </link>




  <joint name="laser_B1_joint" type="fixed">
          <parent link="base_link" />
          <child link="laser_B1_link" />
          <origin xyz="0.483 -0.258 0.0765" rpy="0 0 -0.7854"/>
  </joint>

  <link name="laser_B1_link">
      <visual>
        <origin xyz="0 0 0" rpy="3.1413 0 0"/>
        <geometry>
            <mesh filename="package://rbkairos_63/kuka_kmr_urdf/meshes/sensors/visual/sick_lms1xx.dae" />
        </geometry>
        <material name="dark"/>
      </visual>
      <collision>
          <origin xyz="0.0 0 0.0" rpy="0 0 0"/>
          <geometry>
              <mesh filename="package://rbkairos_63/kuka_kmr_urdf/meshes/sensors/collision/sick_lms1xx.stl" />
          </geometry>
      </collision>
  </link>

  <joint name="laser_B4_joint" type="fixed">
          <parent link="base_link" />
          <child link="laser_B4_link" />
          <origin xyz="-0.483 0.258 0.0765" rpy="0 0 2.3562"/>
  </joint>

  <link name="laser_B4_link">
      <visual>
        <origin xyz="0.0 0 0" rpy="0 3.1413 3.1413"/>
        <geometry>
            <mesh filename="package://rbkairos_63/kuka_kmr_urdf/meshes/sensors/visual/sick_lms1xx.dae" />
        </geometry>
        <material name="dark"/>
      </visual>
      <collision>
          <origin xyz="0 0 0" rpy="0 0 0"/>
          <geometry>
                <mesh filename="package://rbkairos_63/kuka_kmr_urdf/meshes/sensors/collision/sick_lms1xx.stl" />
          </geometry>
      </collision>
  </link>

  <link name="front_left_wheel_link">
      <visual>
        <origin xyz="0 0 0" rpy="0 0 0" />
        <geometry>
          <mesh filename="package://rbkairos_63/kuka_kmr_urdf/meshes/wheels/omni_wheel_1.dae" />
        </geometry>
      </visual>
      <collision>
        <geometry>
          <cylinder length="0.175" radius="0.125" />
        </geometry>
      </collision>

  </link>

  <link name="front_right_wheel_link">
      <visual>
        <origin xyz="0 0 0" rpy="0 0 0" />
        <geometry>
          <mesh filename="package://rbkairos_63/kuka_kmr_urdf/meshes/wheels/omni_wheel_1.dae" />
        </geometry>
      </visual>
      <collision>
        <geometry>
          <cylinder length="0.175" radius="0.125" />
        </geometry>
      </collision>

  </link>

  <link name="back_left_wheel_link">
      <visual>
        <origin xyz="0 0 0" rpy="0 0 0" />
        <geometry>
          <mesh filename="package://rbkairos_63/kuka_kmr_urdf/meshes/wheels/omni_wheel_1.dae" />
        </geometry>
      </visual>
      <collision>
        <geometry>
          <cylinder length="0.175" radius="0.125" />
        </geometry>
      </collision>
  </link>

  <link name="back_right_wheel_link">
      <visual>
        <origin xyz="0 0 0" rpy="0 0 0" />
        <geometry>
          <mesh filename="package://rbkairos_63/kuka_kmr_urdf/meshes/wheels/omni_wheel_1.dae" />
        </geometry>
      </visual>
      <collision>
        <geometry>
          <cylinder length="0.175" radius="0.125" />
        </geometry>
      </collision>
  </link>

  <joint name="front_left_wheel_joint" type="fixed">
      <parent link="base_link"/>
      <child link="front_left_wheel_link"/>
      <axis xyz="0 1 0"/>
      <origin xyz="0.28 0.1825 0.0535"/>
      <limit effort="100" velocity="100"/>
     
  </joint>

  <joint name="front_right_wheel_joint" type="fixed">
      <parent link="base_link"/>
      <child link="front_right_wheel_link"/>
      <origin xyz="0.28 -0.1825 0.0535"/>
      <axis xyz="0 1 0"/>
      <limit effort="100" velocity="100"/>
     
  </joint>

  <joint name="back_left_wheel_joint" type="fixed">
      <parent link="base_link"/>
      <child link="back_left_wheel_link"/>
      <origin xyz="-0.28 0.1825 0.0535"/>
      <axis xyz="0 1 0"/>
      <limit effort="100" velocity="100"/>
     
  </joint>

  <joint name="back_right_wheel_joint" type="fixed">
      <parent link="base_link"/>
      <child link="back_right_wheel_link"/>
      <origin xyz="-0.28 -0.1825 0.0535"/>
      <axis xyz="0 1 0"/>
      <limit effort="100" velocity="100"/>
     
  </joint>

      <joint name="base_link-to-iiwa" type="fixed">
      <origin rpy="0 0 -1.5708" xyz="0.363 -0.184 0.2625"/>
      <parent link="base_link_top"/>
      <child link="base_iiwa"/>
  </joint>

  <link name="base_iiwa">
      <visual>
        <origin rpy="0.0 0 0" xyz="0 0 0"/>
        <geometry>
          <mesh filename="package://rbkairos_63/kuka_kmr_urdf/meshes/lbr_iiwa_14_r820/visual/base_link.dae"/>
        </geometry>
      </visual>
      <collision>
        <origin rpy="0 0 0" xyz="0 0 0"/>
        <geometry>
          <mesh filename="package://rbkairos_63/kuka_kmr_urdf/meshes/lbr_iiwa_14_r820/collision/base_link.stl"/>
        </geometry>
      </collision>
  </link>
  <link name="link_1">
      <visual>
        <origin rpy="0 0 0" xyz="0 0 0"/>
        <geometry>
          <mesh filename="package://rbkairos_63/kuka_kmr_urdf/meshes/lbr_iiwa_14_r820/visual/link_1.dae"/>
        </geometry>
      </visual>
      <collision>
        <origin rpy="0 0 0" xyz="0 0 0"/>
        <geometry>
          <mesh filename="package://rbkairos_63/kuka_kmr_urdf/meshes/lbr_iiwa_14_r820/collision/link_1.stl"/>
        </geometry>
      </collision>
  </link>
  <link name="link_2">
      <visual>
        <origin rpy="0 0 0" xyz="0 0 0"/>
        <geometry>
          <mesh filename="package://rbkairos_63/kuka_kmr_urdf/meshes/lbr_iiwa_14_r820/visual/link_2.dae"/>
        </geometry>
      </visual>
      <collision>
        <origin rpy="0 0 0" xyz="0 0 0"/>
        <geometry>
          <mesh filename="package://rbkairos_63/kuka_kmr_urdf/meshes/lbr_iiwa_14_r820/collision/link_2.stl"/>
        </geometry>
      </collision>
  </link>
  <link name="link_3">
      <visual>
        <origin rpy="0 0 0" xyz="0 0 0"/>
        <geometry>
          <mesh filename="package://rbkairos_63/kuka_kmr_urdf/meshes/lbr_iiwa_14_r820/visual/link_3.dae"/>
        </geometry>
      </visual>
      <collision>
        <origin rpy="0 0 0" xyz="0 0 0"/>
        <geometry>
          <mesh filename="package://rbkairos_63/kuka_kmr_urdf/meshes/lbr_iiwa_14_r820/collision/link_3.stl"/>
        </geometry>
      </collision>
  </link>
  <link name="link_4">
      <visual>
        <origin rpy="0 0 0" xyz="0 0 0"/>
        <geometry>
          <mesh filename="package://rbkairos_63/kuka_kmr_urdf/meshes/lbr_iiwa_14_r820/visual/link_4.dae"/>
        </geometry>
      </visual>
      <collision>
        <origin rpy="0 0 0" xyz="0 0 0"/>
        <geometry>
          <mesh filename="package://rbkairos_63/kuka_kmr_urdf/meshes/lbr_iiwa_14_r820/collision/link_4.stl"/>
        </geometry>
      </collision>
  </link>
  <link name="link_5">
      <visual>
        <origin rpy="0 0 0" xyz="0 0 0"/>
        <geometry>
          <mesh filename="package://rbkairos_63/kuka_kmr_urdf/meshes/lbr_iiwa_14_r820/visual/link_5.dae"/>
        </geometry>
      </visual>
      <collision>
        <origin rpy="0 0 0" xyz="0 0 0"/>
        <geometry>
          <mesh filename="package://rbkairos_63/kuka_kmr_urdf/meshes/lbr_iiwa_14_r820/collision/link_5.stl"/>
        </geometry>
      </collision>
  </link>
  <link name="link_6">
      <visual>
        <origin rpy="0 0 0" xyz="0 0 0"/>
        <geometry>
          <mesh filename="package://rbkairos_63/kuka_kmr_urdf/meshes/lbr_iiwa_14_r820/visual/link_6.dae"/>
        </geometry>
      </visual>
      <collision>
        <origin rpy="0 0 0" xyz="0 0 0"/>
        <geometry>
          <mesh filename="package://rbkairos_63/kuka_kmr_urdf/meshes/lbr_iiwa_14_r820/collision/link_6.stl"/>
        </geometry>
      </collision>
  </link>
  <link name="link_7">
      <visual>
        <origin rpy="0 0 0" xyz="0 0 0"/>
        <geometry>
          <mesh filename="package://rbkairos_63/kuka_kmr_urdf/meshes/lbr_iiwa_14_r820/visual/link_7.dae"/>
        </geometry>
      </visual>
      <collision>
        <origin rpy="0 0 0" xyz="0 0 0"/>
        <geometry>
          <mesh filename="package://rbkairos_63/kuka_kmr_urdf/meshes/lbr_iiwa_14_r820/collision/link_7.stl"/>
        </geometry>
      </collision>
  </link>


  <joint name="joint_a1" type="revolute">
      <origin rpy="0 0 0" xyz="0 0 0"/>
      <parent link="base_iiwa"/>
      <child link="link_1"/>
      <axis xyz="0 0 1"/>
      <limit effort="0" lower="-2.9668" upper="2.9668" velocity="1.4834"/>
  </joint>
  <joint name="joint_a2" type="revolute">
      <origin rpy="0 0 0" xyz="-0.00043624 0 0.36"/>
      <parent link="link_1"/>
      <child link="link_2"/>
      <axis xyz="0 1 0"/>
      <limit effort="0" lower="-2.0942" upper="2.0942" velocity="1.4834"/>
  </joint>
  <joint name="joint_a3" type="revolute">
      <origin rpy="0 0 0" xyz="0 0 0"/>
      <parent link="link_2"/>
      <child link="link_3"/>
      <axis xyz="0 0 1"/>
      <limit effort="0" lower="-2.9668" upper="2.9668" velocity="1.7452"/>
  </joint>
  <joint name="joint_a4" type="revolute">
      <origin rpy="0 0 0" xyz="0.00043624 0 0.42"/>
      <parent link="link_3"/>
      <child link="link_4"/>
      <axis xyz="0 -1 0"/>
      <limit effort="0" lower="-2.0942" upper="2.0942" velocity="1.3089"/>
  </joint>
  <joint name="joint_a5" type="revolute">
      <origin rpy="0 0 0" xyz="0 0 0"/>
      <parent link="link_4"/>
      <child link="link_5"/>
      <axis xyz="0 0 1"/>
      <limit effort="0" lower="-2.9668" upper="2.9668" velocity="2.2688"/>
  </joint>
  <joint name="joint_a6" type="revolute">
      <origin rpy="0 0 0" xyz="0 0 0.4"/>
      <parent link="link_5"/>
      <child link="link_6"/>
      <axis xyz="0 1 0"/>
      <limit effort="0" lower="-2.0942" upper="2.0942" velocity="2.356"/>
  </joint>
  <joint name="joint_a7" type="revolute">
      <origin rpy="0 0 0" xyz="0 0 0"/>
      <parent link="link_6"/>
      <child link="link_7"/>
      <axis xyz="0 0 1"/>
      <limit effort="0" lower="-3.0541" upper="3.0541" velocity="2.356"/>
  </joint>

  <joint name="joint_a7-adapter" type="fixed">
      <origin rpy="0 0 -0.785398" xyz="0 0 0.1365"/>
      <parent link="link_7"/>
      <child link="adapter"/>
      <axis xyz="0 0 0"/>
  </joint>

  <link name="adapter">
    <visual>
      <origin xyz="0 0 0" rpy="0 0 0" />
      <geometry>
        <cylinder length="0.035" radius="0.0375" />
      </geometry>
      <material name="aluminum"/>
    </visual>
  </link>

  <joint name="joint_adapter-feste1" type="fixed">
      <origin rpy="0 0 0" xyz="-0.0425 0 0.0125"/>
      <parent link="adapter"/>
      <child link="kamerafeste1"/>
      <axis xyz="0 0 0"/>
  </joint>
  
  <link name="kamerafeste1">
    <visual>
      <origin xyz="0 0 0" rpy="0 0 0" />
      <geometry>
        <box size="0.01 0.015 0.01"/>
      </geometry>
      <material name="aluminum"/>
    </visual>
  </link>

  <joint name="joint_adapter-feste2" type="fixed">
      <origin rpy="0 0 0" xyz="-0.01 0 0.005"/>
      <parent link="kamerafeste1"/>
      <child link="kamerafeste2"/>
      <axis xyz="0 0 0"/>
  </joint>

  <link name="kamerafeste2">
    <visual>
      <origin xyz="0 0 0" rpy="0 0 0" />
      <geometry>
        <box size="0.01 0.015 0.02"/>
      </geometry>
      <material name="aluminum"/>
    </visual>
  </link>

  <!-- Manipulator camera, with origin at bottom screw mount -->
    <joint name="d435_manipulator_joint" type="fixed">
      <origin xyz="-0.005 0.0 0.005" rpy="0 -1.570796 0"/>
      <parent link="kamerafeste2"/>
      <child link="d435_manipulator_link" />
    </joint>

    <link name="d435_manipulator_link">
      <visual>
      <origin xyz="0.0149 0.0 0.0125" rpy="1.570796 0 1.570796 "/>
        <geometry>
	        <mesh filename="package://rbkairos_63/kuka_kmr_urdf/meshes/sensors/visual/d435.dae" />
        </geometry>
        <material name="aluminum"/>
      </visual>
      <collision>
        <origin xyz="0.0149 0.0 0.0125" rpy="3.1415 1.570796 0 "/>
        <geometry>
        <box size="0.02505 0.090 0.025"/>
        </geometry>
      </collision>
    </link>
    <!--  -->

    <joint name="d435_manipulator_depth_joint" type="fixed">
      <origin xyz="0.0149 -0.0075 0.0125" rpy="0 0 0"/>
      <parent link="d435_manipulator_link"/>
      <child link="d435_manipulator_depth_frame" />
    </joint>

    <link name="d435_manipulator_depth_frame"/>

    <joint name="d435_manipulator_depth_optical_joint" type="fixed">
      <origin xyz="0 0 0" rpy="-1.570796 0 -1.570796" />
      <parent link= "d435_manipulator_depth_frame" />
      <child link="d435_manipulator_depth_optical_frame" />
    </joint>

    <link name="d435_manipulator_depth_optical_frame"/>


  <joint name="joint_adapter-gripperadapter" type="fixed">
      <origin rpy="0 0 0" xyz="0 0 0.0255"/>
      <parent link="adapter"/>
      <child link="gripper-adapter"/>
      <axis xyz="0 0 0"/>
  </joint>

  <link name="gripper-adapter">
    <visual>
      <origin xyz="0 0 0" rpy="0 0 0" />
      <geometry>
        <cylinder length="0.016" radius="0.0375" />
      </geometry>
      <material name="Black"/>
    </visual>
  </link>

  <joint name="joint_gripperadapter-gripper" type="fixed">
      <origin rpy="0 0 0" xyz="0 0 0.008"/>
      <parent link="gripper-adapter"/>
      <child link="gripper_base_link"/>
      <axis xyz="0 0 0"/>
  </joint>


  <link name="gripper_base_link">
    <visual>
      <origin xyz="0 0 0" rpy="0 0 0" />
      <geometry>
        <mesh filename="package://rbkairos_63/kuka_kmr_urdf/meshes/gripper/visual/robotiq_arg2f_85_base_link.dae" scale="0.001 0.001 0.001"/>
      </geometry>
      <material name="aluminum"/>
    </visual>
    <collision>
      <origin xyz="0 0 0" rpy="0 0 0" />
      <geometry>
        <mesh filename="package://rbkairos_63/kuka_kmr_urdf/meshes/gripper/collision/robotiq_arg2f_base_link.stl" />
      </geometry>
    </collision>
  </link>

  <joint name="right_outer_knuckle_joint" type="fixed">
      <origin xyz="0 0.0306011 0.054904" rpy="0 0 0"/>
      <parent link="gripper_base_link" />
      <child link="right_outer_knuckle" />
      <axis xyz="1 0 0" />
      <limit lower="0" upper="0.81" velocity="2.0" effort="1000" />
    </joint>

    <link name="left_outer_knuckle">
      <visual>
        <origin xyz="0 0 0" rpy="0 0 0" />
        <geometry>
          <mesh filename="package://rbkairos_63/kuka_kmr_urdf/meshes/gripper/visual/robotiq_arg2f_85_outer_knuckle.dae" scale="0.001 0.001 0.001"/>
        </geometry>
        <material name="aluminum"/>
      </visual>
      <collision>
        <origin xyz="0 0 0" rpy="0 0 0" />
        <geometry>
          <mesh filename="package://rbkairos_63/kuka_kmr_urdf/meshes/gripper/collision/robotiq_arg2f_85_outer_knuckle.dae" scale="0.001 0.001 0.001"/>
        </geometry>
      </collision>
    </link>
    <link name="right_outer_knuckle">
      <visual>
        <origin xyz="0 0 0" rpy="0 0 0" />
        <geometry>
          <mesh filename="package://rbkairos_63/kuka_kmr_urdf/meshes/gripper/visual/robotiq_arg2f_85_outer_knuckle.dae" scale="0.001 0.001 0.001"/>
        </geometry>
        <material name="aluminum"/>
      </visual>
      <collision>
        <origin xyz="0 0 0" rpy="0 0 0" />
        <geometry>
          <mesh filename="package://rbkairos_63/kuka_kmr_urdf/meshes/gripper/collision/robotiq_arg2f_85_outer_knuckle.dae" scale="0.001 0.001 0.001"/>
        </geometry>
      </collision>
    </link>

    <link name="left_outer_finger">
      <visual>
        <origin xyz="0 0 0" rpy="0 0 0" />
        <geometry>
          <mesh filename="package://rbkairos_63/kuka_kmr_urdf/meshes/gripper/visual/robotiq_arg2f_85_outer_finger.dae" scale="0.001 0.001 0.001"/>
        </geometry>
        <material name="aluminum"/>
      </visual>
      <collision>
        <origin xyz="0 0 0" rpy="0 0 0" />
        <geometry>
          <mesh filename="package://rbkairos_63/kuka_kmr_urdf/meshes/gripper/collision/robotiq_arg2f_85_outer_finger.dae" scale="0.001 0.001 0.001"/>
        </geometry>
      </collision>
    </link>

    <link name="right_outer_finger">
      <visual>
        <origin xyz="0 0 0" rpy="0 0 0" />
        <geometry>
          <mesh filename="package://rbkairos_63/kuka_kmr_urdf/meshes/gripper/visual/robotiq_arg2f_85_outer_finger.dae" scale="0.001 0.001 0.001"/>
        </geometry>
        <material name="aluminum"/>
      </visual>
      <collision>
        <origin xyz="0 0 0" rpy="0 0 0" />
        <geometry>
          <mesh filename="package://rbkairos_63/kuka_kmr_urdf/meshes/gripper/collision/robotiq_arg2f_85_outer_finger.dae" scale="0.001 0.001 0.001"/>
        </geometry>
      </collision>
    </link>

    <link name="left_inner_knuckle">
      <visual>
        <origin xyz="0 0 0" rpy="0 0 0" />
        <geometry>
          <mesh filename="package://rbkairos_63/kuka_kmr_urdf/meshes/gripper/visual/robotiq_arg2f_85_inner_knuckle.dae" scale="0.001 0.001 0.001"/>
        </geometry>
        <material name="aluminum"/>
      </visual>
      <collision>
        <origin xyz="0 0 0" rpy="0 0 0" />
        <geometry>
          <mesh filename="package://rbkairos_63/kuka_kmr_urdf/meshes/gripper/collision/robotiq_arg2f_85_inner_knuckle.dae" scale="0.001 0.001 0.001"/>
        </geometry>
      </collision>
    </link>

    <link name="right_inner_knuckle">
      <visual>
        <origin xyz="0 0 0" rpy="0 0 0" />
        <geometry>
          <mesh filename="package://rbkairos_63/kuka_kmr_urdf/meshes/gripper/visual/robotiq_arg2f_85_inner_knuckle.dae" scale="0.001 0.001 0.001"/>
        </geometry>
        <material name="aluminum"/>
      </visual>
      <collision>
        <origin xyz="0 0 0" rpy="0 0 0" />
        <geometry>
          <mesh filename="package://rbkairos_63/kuka_kmr_urdf/meshes/gripper/collision/robotiq_arg2f_85_inner_knuckle.dae" scale="0.001 0.001 0.001"/>
        </geometry>
      </collision>
    </link>

    <link name="left_inner_finger">

      <visual>
        <origin xyz="0 0 0" rpy="0 0 0" />
        <geometry>
          <mesh filename="package://rbkairos_63/kuka_kmr_urdf/meshes/gripper/visual/robotiq_arg2f_85_inner_finger.dae" scale="0.001 0.001 0.001"/>
        </geometry>
        <material name="aluminum"/>
      </visual>
      <collision>
        <origin xyz="0 0 0" rpy="0 0 0" />
        <geometry>
          <mesh filename="package://rbkairos_63/kuka_kmr_urdf/meshes/gripper/collision/robotiq_arg2f_85_inner_finger.dae" scale="0.001 0.001 0.001" />
        </geometry>
      </collision>
    </link>

    <link name="right_inner_finger">
      <visual>
        <origin xyz="0 0 0" rpy="0 0 0" />
        <geometry>
          <mesh filename="package://rbkairos_63/kuka_kmr_urdf/meshes/gripper/visual/robotiq_arg2f_85_inner_finger.dae" scale="0.001 0.001 0.001"/>
        </geometry>
        <material name="aluminum"/>
      </visual>
      <collision>
        <origin xyz="0 0 0" rpy="0 0 0" />
        <geometry>
          <mesh filename="package://rbkairos_63/kuka_kmr_urdf/meshes/gripper/collision/robotiq_arg2f_85_inner_finger.dae" scale="0.001 0.001 0.001" />
        </geometry>
      </collision>
    </link>

   <!-- Finger pad link, the default are the "big pads" with rubber-->
    <link name="left_inner_finger_pad">
      <visual>
        <origin xyz="0 0 0" rpy="0 0 0" />
        <geometry>
          <box size="0.022 0.00635 0.0375"/>
        </geometry>
        <material name="aluminum"/>
      </visual>
      <collision>
        <origin xyz="0 0 0" rpy="0 0 0" />
        <geometry>
           <box size="0.022 0.00635 0.0375"/>
        </geometry>
      </collision>
    </link>
    <link name="right_inner_finger_pad">
      <visual>
        <origin xyz="0 0 0" rpy="0 0 0" />
        <geometry>
          <box size="0.022 0.00635 0.0375"/>
        </geometry>
        <material name="aluminum"/>
      </visual>
      <collision>
        <origin xyz="0 0 0" rpy="0 0 0" />
        <geometry>
           <box size="0.022 0.00635 0.0375"/>
        </geometry>
      </collision>
    </link>

    <joint name="gripper_middle_point" type="fixed">
      <origin xyz="0 0.0 0.144" rpy="0 0 0"/>
      <parent link="gripper_base_link" />
      <child link="gripper_middle_point" />
    </joint>
    <link name="gripper_middle_point"/>

    <joint name="left_outer_finger_joint" type="fixed">
      <origin xyz="0 0.0315 -0.0041" rpy="0 0 0"/>
      <parent link="left_outer_knuckle" />
      <child link="left_outer_finger" />
      <axis xyz="1 0 0" />
    </joint>

    <joint name="right_outer_finger_joint" type="fixed">
      <origin xyz="0 0.0315 -0.0041" rpy="0 0 0"/>
      <parent link="right_outer_knuckle" />
      <child link="right_outer_finger" />
      <axis xyz="1 0 0" />
    </joint>

    <joint name="left_inner_knuckle_joint" type="fixed">
      <origin xyz="0 -0.0127 0.06142" rpy="0 0 3.1415"/>
      <parent link="gripper_base_link" />
      <child link="left_inner_knuckle" />
      <axis xyz="1 0 0" />
      <limit lower="0" upper="0.8757" velocity="2.0" effort="1000" />
    </joint>

    <joint name="right_inner_knuckle_joint" type="fixed">
      <origin xyz="0 0.0127 0.06142" rpy="0 0 0"/>
      <parent link="gripper_base_link" />
      <child link="right_inner_knuckle" />
      <axis xyz="1 0 0" />
      <limit lower="0" upper="0.8757" velocity="2.0" effort="1000" />
    </joint>

    <joint name="left_inner_finger_joint" type="fixed">
      <origin xyz="0 0.0061 0.0471" rpy="0 0 0"/>
      <parent link="left_outer_finger" />
      <child link="left_inner_finger" />
      <axis xyz="1 0 0" />
      <limit lower="0" upper="0.8757" velocity="2.0" effort="1000" />
    </joint>

    <joint name="right_inner_finger_joint" type="fixed">
      <origin xyz="0 0.0061 0.0471" rpy="0 0 0"/>
      <parent link="right_outer_finger" />
      <child link="right_inner_finger" />
      <axis xyz="1 0 0" />
      <limit lower="0" upper="0.8757" velocity="2.0" effort="1000" />
    </joint>


    <joint name="left_inner_finger_pad_joint" type="fixed">
      <origin xyz="0 -0.0220203446692936 0.03242" rpy="0 0 0"/>
      <parent link="left_inner_finger" />
      <child link="left_inner_finger_pad" />
      <axis xyz="0 0 1" />
    </joint>

    <joint name="right_inner_finger_pad_joint" type="fixed">
      <origin xyz="0 -0.0220203446692936 0.03242" rpy="0 0 0"/>
      <parent link="right_inner_finger" />
      <child link="right_inner_finger_pad" />
      <axis xyz="0 0 1" />
    </joint>

    <joint name="finger_joint" type="fixed">
      <origin xyz="0 -0.0306011 0.054904" rpy="0 0 3.1415"/>
      <parent link="gripper_base_link" />
      <child link="left_outer_knuckle" />
      <axis xyz="1 0 0" />
      <limit lower="0" upper="0.8" velocity="2.0" effort="1000" />
    </joint>

    
    <!-- camera body, with origin at bottom screw mount -->
    <joint name="d435_base_front_joint" type="fixed">
      <origin xyz="0.52 0.0 0.2625" rpy="0 0 0"/>
      <parent link="base_link_top"/>
      <child link="d435_base_front_link" />
    </joint>

    <link name="d435_base_front_link">
      <visual>
      <origin xyz="0.0149 0.0 0.0125" rpy="1.570796 0 1.570796"/>
        <geometry>
	        <mesh filename="package://rbkairos_63/kuka_kmr_urdf/meshes/sensors/visual/d435.dae" />
        </geometry>
        <material name="aluminum"/>
      </visual>
      <collision>
        <origin xyz="0.0 0.0 0.0125" rpy="0 0 0"/>
        <geometry>
        <box size="0.02505 0.090 0.025"/>
        </geometry>
      </collision>
    </link>
   
    <!-- camera depth joints and links -->
    <joint name="d435_base_front_depth_joint" type="fixed">
      <origin xyz="0.0149 -0.0075 0.0125" rpy="0 0 0"/>
      <parent link="d435_base_front_link"/>
      <child link="d435_base_front_depth_frame" />
    </joint>

    <link name="d435_base_front_depth_frame"/>

    <joint name="d435_base_front_depth_optical_joint" type="fixed">
      <origin xyz="0 0 0" rpy="-1.570796 0 -1.570796" />
      <parent link= "d435_base_front_depth_frame" />
      <child link="d435_base_front_depth_optical_frame" />
    </joint>

    <link name="d435_base_front_depth_optical_frame"/>



    <joint name="metall_plate_left_joint" type="fixed">
      <origin xyz="-0.08 0.28 0.2675" rpy="0 0 0"/>
      <parent link="base_link_top"/>
      <child link="metall_plate_left_link" />
    </joint>

    <link name="metall_plate_left_link">
      <visual>
        <origin xyz="0.0 0.0 0.0" rpy="0.0 0 0.0 "/>
          <geometry>
            <box size="0.2 0.04 0.01"/>
          </geometry>
          <material name="aluminum"/>
      </visual>
      <collision>
        <origin xyz="0.0 0.0 0.0" rpy="0.0 0 0.0 "/>
          <geometry>
            <box size="0.2 0.04 0.01"/>
          </geometry>
      </collision>
    </link>


  <!-- D435 camera on the base - left side, with origin at bottom screw mount -->
    <joint name="d435_base_left_joint" type="fixed">
      <origin xyz="0.0 0.0 0.005" rpy="0 0.0 1.570796"/>
      <parent link="metall_plate_left_link"/>
      <child link="d435_base_left_link" />
    </joint>

    <link name="d435_base_left_link">
      <visual>
      <origin xyz="0.0149 0.0 0.0125" rpy="1.570796 0 1.570796 "/>
        <geometry>
	        <mesh filename="package://rbkairos_63/kuka_kmr_urdf/meshes/sensors/visual/d435.dae" />
        </geometry>
        <material name="aluminum"/>
      </visual>
      <collision>
        <origin xyz="0.0149 0.0 0.0125" rpy="3.1415 1.570796 0 "/>
        <geometry>
        <box size="0.02505 0.090 0.025"/>
        </geometry>
      </collision>
    </link>
    <!--  -->

    <joint name="metall_plate_right_joint" type="fixed">
      <origin xyz="-0.08 -0.28 0.2675" rpy="0 0 0"/>
      <parent link="base_link_top"/>
      <child link="metall_plate_right_link" />
    </joint>

    <link name="metall_plate_right_link">
      <visual>
        <origin xyz="0.0 0.0 0.0" rpy="0.0 0 0.0 "/>
          <geometry>
            <box size="0.2 0.04 0.01"/>
          </geometry>
          <material name="aluminum"/>
      </visual>
      <collision>
        <origin xyz="0.0 0.0 0.0" rpy="0.0 0 0.0 "/>
          <geometry>
            <box size="0.2 0.04 0.01"/>
          </geometry>
      </collision>
    </link>


  <!-- D435 camera on the base - right side, with origin at bottom screw mount -->
    <joint name="d435_base_right_joint" type="fixed">
      <origin xyz="0.0 0.0 0.005" rpy="0 0 -1.570796"/>
      <parent link="metall_plate_right_link"/>
      <child link="d435_base_right_link" />
    </joint>

    <link name="d435_base_right_link">
      <visual>
      <origin xyz="0.0149 0.0 0.0125" rpy="1.570796 0 1.570796 "/>
        <geometry>
	        <mesh filename="package://rbkairos_63/kuka_kmr_urdf/meshes/sensors/visual/d435.dae" />
        </geometry>
        <material name="aluminum"/>
      </visual>
      <collision>
        <origin xyz="0.0149 0.0 0.0125" rpy="3.1415 1.570796 0 "/>
        <geometry>
          <box size="0.02505 0.090 0.025"/>
        </geometry>
      </collision>
    </link>
    <!--  -->
</robot>
